<?xml version='1.0'?>

<robot name="my_robot" xmlns:xacro="http://www.ros.org/wiki/xacro">

<xacro:include filename="$(find my_robot)/urdf/my_robot.gazebo" />

<gazebo reference="chassis">
    <material>Gazebo/Green</material>
</gazebo>


  <link name="robot_footprint"></link>

  <joint name="robot_footprint_joint" type="fixed">
    <origin xyz="0 0 0" rpy="0 0 0" />
    <parent link="robot_footprint"/>
    <child link="chassis" />
  </joint>

  <link name='chassis'>
    <pose>0 0 0.05 0 0 0</pose>

    <inertial>
      <mass value="15.0"/>
      <origin xyz="0.0 0 0" rpy=" 0 0 0"/>
      <inertia
          ixx="0.1" ixy="0" ixz="0"
          iyy="0.1" iyz="0"
          izz="0.1"
      />
    </inertial>

    <collision name='collision'>
      <origin xyz="0 0 0" rpy=" 0 0 0"/> 
      <geometry>
        <box size=".8 .2 .025"/>
      </geometry>
    </collision>

    <visual name='chassis_visual'>
      <origin xyz="0 0 0" rpy=" 0 0 0"/>
      <geometry>
        <box size=".8 .2 .025"/>
      </geometry>
	<material name="Green">
         <color rgba="0 1.0 1.0 1"/>
        </material>
    </visual>


    <collision name='back_caster_collision'>
      <origin xyz="-0.3 0 -0.025" rpy=" 0 0 0"/>
      <geometry>
        <sphere radius="0.02499"/>
      </geometry>
    </collision>

    <visual name='back_caster_visual'>
      <origin xyz="-0.3 0 -0.025" rpy=" 0 0 0"/>
      <geometry>
        <sphere radius="0.025"/>
      </geometry>
    </visual>

    <collision name='front_caster_collision'>
      <origin xyz="0.3 0 -0.025" rpy=" 0 0 0"/>
      <geometry>
        <sphere radius="0.02499"/>
      </geometry>
    </collision>

    <visual name='front_caster_visual'>
      <origin xyz="0.3 0 -0.025" rpy=" 0 0 0"/>
      <geometry>
        <sphere radius="0.025"/>
      </geometry>
    </visual>

  </link>

  <link name="left_wheel">
     <collision>
	<geometry>
		<cylinder radius="0.05" length ="0.05"/>
	</geometry>
	<origin xyz =" 0 0 0" rpy = " 0 1.5707 1.5707" />
     </collision>
	
<visual name='Lsideweheel_visual'>
      <origin xyz="0 0 0" rpy=" 0 1.5707 1.5707"/>
      <geometry>
        <cylinder radius="0.05" length ="0.05"/>
      </geometry>
    </visual>

<inertial>
      <mass value="5.0"/>
      <origin xyz="0.0 0 0" rpy=" 0 1.5707 1.5707"/>
      <inertia
          ixx="0.1" ixy="0" ixz="0"
          iyy="0.1" iyz="0"
          izz="0.1"
      />
    </inertial>
      
</link>

  <link name="right_wheel">
     <collision>
	<geometry>
		<cylinder radius="0.05" length ="0.05"/>
	</geometry>
	<origin xyz =" 0 0 0" rpy = " 0 1.5707 1.5707" />
     </collision>
	
<visual name='Lsideweheel_visual'>
      <origin xyz="0 0 0" rpy=" 0 1.5707 1.5707"/>
      <geometry>
        <cylinder radius="0.05" length ="0.05"/>
      </geometry>
    </visual>

<inertial>
      <mass value="5.0"/>
      <origin xyz="0.0 0 0" rpy=" 0 1.5707 1.5707"/>
      <inertia
          ixx="0.1" ixy="0" ixz="0"
          iyy="0.1" iyz="0"
          izz="0.1"
      />
    </inertial>
      
</link>


  <link name="camera">
     <collision>
	<geometry>
		<box size ="0.05 0.05 0.05"/>
	</geometry>
	<origin xyz =" 0 0 0" rpy = " 0 0 0" />
     </collision>
	
     <visual name='camera'>
    	 <geometry>
		<box size ="0.05 0.05 0.05"/>
    	 </geometry>
     <origin xyz =" 0 0 0" rpy = " 0 0 0" />
     </visual>

     <inertial>
      <mass value="0.5"/>
      <origin xyz="0.05 0.05 0.05" rpy=" 0 0 0"/>
      <inertia
          ixx="0.000001" ixy="0" ixz="0"
          iyy="0.000001" iyz="0"
          izz="0.000001"
      />
    </inertial>

</link>

  <link name="hokuyo">
     <collision>
	<geometry>
		<box size ="0.1 0.1 0.1"/>
	</geometry>
	<origin xyz =" 0 0 0" rpy = " 0 0 0" />
     </collision>
	
     <visual name='hokuyo'>
    	 <geometry>
		<mesh filename = "package://my_robot/meshes/hokuyo.dae"/>
    	 </geometry>
     <origin xyz =" 0 0 0" rpy = " 0 0 0" />
     </visual>

     <inertial>
      <mass value="1e-5"/>
      <origin xyz="0 0 0" rpy=" 0 0 0"/>
      <inertia
          ixx="0.000001" ixy="0" ixz="0"
          iyy="0.000001" iyz="0"
          izz="0.000001"
      />
    </inertial>
      
</link>

<joint type="continuous" name="left_wheel_hinge">
    <origin xyz="0 0.15 0" rpy="0 0 0"/>
    <child link="left_wheel"/>
    <parent link="chassis"/>
    <axis xyz="0 1 0" rpy="0 0 0"/>
    <limit effort="10000" velocity="1000"/>
    <dynamics damping="1.0" friction="1.0"/>
  </joint>

<joint type="continuous" name="right_wheel_hinge">
    <origin xyz="0 -0.15 0" rpy="0 0 0"/>
    <child link="right_wheel"/>
    <parent link="chassis"/>
    <axis xyz="0 1 0" rpy="0 0 0"/>
    <limit effort="10000" velocity="1000"/>
    <dynamics damping="1.0" friction="1.0"/>
  </joint>

<joint type="fixed" name="camera_joint">
    <origin xyz="0.4 0 0" rpy="0 0 0"/>
    <child link="camera"/>
    <parent link="chassis"/>
    <axis xyz="0 1 0" rpy="0 0 0"/>
    <limit effort="10000" velocity="1000"/>
    <dynamics damping="1.0" friction="1.0"/>
  </joint>

<joint type="fixed" name="hokuyo_joint">
    <origin xyz="0.2 0 0.05" rpy="0 0 0"/>
    <child link="hokuyo"/>
    <parent link="chassis"/>
    <axis xyz="0 1 0" rpy="0 0 0"/>
    <limit effort="10000" velocity="1000"/>
    <dynamics damping="1.0" friction="1.0"/>
  </joint>


</robot>
